<?xml version="1.0" ?>
<robot name="trialin1_v1" xmlns:xacro="http://www.ros.org/wiki/xacro">

<xacro:include filename="$(find trialin1_v1_description)/urdf/materials.xacro" />
<xacro:include filename="$(find trialin1_v1_description)/urdf/trialin1_v1.trans" />
<xacro:include filename="$(find trialin1_v1_description)/urdf/trialin1_v1.gazebo" />
<link name="base_link">
  <inertial>
    <origin xyz="0.18719085753005504 -0.1252163398372124 0.3067650276389592" rpy="0 0 0"/>
    <mass value="6.0526001728054935"/>
    <inertia ixx="0.121776" iyy="0.168003" izz="0.153906" ixy="-0.0" iyz="0.0" ixz="0.019067"/>
  </inertial>
  <visual>
    <origin xyz="0 0 0" rpy="0 0 0"/>
    <geometry>
      <mesh filename="file://$(find trialin1_v1_description)/meshes/base_link.stl" scale="0.001 0.001 0.001"/>
    </geometry>
    <material name="silver"/>
  </visual>
  <collision>
    <origin xyz="0 0 0" rpy="0 0 0"/>
    <geometry>
      <mesh filename="file://$(find trialin1_v1_description)/meshes/base_link.stl" scale="0.001 0.001 0.001"/>
    </geometry>
  </collision>
</link>

<link name="DS51_Start_horn_v1_1">
  <inertial>
    <origin xyz="2.0184479510021447e-07 -3.3983710490126384e-07 -0.0005610327023830575" rpy="0 0 0"/>
    <mass value="0.027770568475082406"/>
    <inertia ixx="3e-06" iyy="3e-06" izz="6e-06" ixy="0.0" iyz="-0.0" ixz="0.0"/>
  </inertial>
  <visual>
    <origin xyz="-0.068936 0.125216 -0.607305" rpy="0 0 0"/>
    <geometry>
      <mesh filename="file://$(find trialin1_v1_description)/meshes/DS51_Start_horn_v1_1.stl" scale="0.001 0.001 0.001"/>
    </geometry>
    <material name="silver"/>
  </visual>
  <collision>
    <origin xyz="-0.068936 0.125216 -0.607305" rpy="0 0 0"/>
    <geometry>
      <mesh filename="file://$(find trialin1_v1_description)/meshes/DS51_Start_horn_v1_1.stl" scale="0.001 0.001 0.001"/>
    </geometry>
  </collision>
</link>

<link name="DS51_Start_horn_v1__2__1">
  <inertial>
    <origin xyz="2.0184479547491474e-07 -3.398373241980668e-07 0.0005609933386103994" rpy="0 0 0"/>
    <mass value="0.027770568475082406"/>
    <inertia ixx="3e-06" iyy="3e-06" izz="6e-06" ixy="-0.0" iyz="-0.0" ixz="0.0"/>
  </inertial>
  <visual>
    <origin xyz="-0.054436 0.235216 -0.150035" rpy="0 0 0"/>
    <geometry>
      <mesh filename="file://$(find trialin1_v1_description)/meshes/DS51_Start_horn_v1__2__1.stl" scale="0.001 0.001 0.001"/>
    </geometry>
    <material name="silver"/>
  </visual>
  <collision>
    <origin xyz="-0.054436 0.235216 -0.150035" rpy="0 0 0"/>
    <geometry>
      <mesh filename="file://$(find trialin1_v1_description)/meshes/DS51_Start_horn_v1__2__1.stl" scale="0.001 0.001 0.001"/>
    </geometry>
  </collision>
</link>

<link name="DS51_Start_horn_v1__1__1">
  <inertial>
    <origin xyz="2.0184479626594864e-07 -3.3983731831388475e-07 0.0005609933386111765" rpy="0 0 0"/>
    <mass value="0.027770568475082406"/>
    <inertia ixx="3e-06" iyy="3e-06" izz="6e-06" ixy="0.0" iyz="-0.0" ixz="0.0"/>
  </inertial>
  <visual>
    <origin xyz="-0.354936 0.235216 -0.150035" rpy="0 0 0"/>
    <geometry>
      <mesh filename="file://$(find trialin1_v1_description)/meshes/DS51_Start_horn_v1__1__1.stl" scale="0.001 0.001 0.001"/>
    </geometry>
    <material name="silver"/>
  </visual>
  <collision>
    <origin xyz="-0.354936 0.235216 -0.150035" rpy="0 0 0"/>
    <geometry>
      <mesh filename="file://$(find trialin1_v1_description)/meshes/DS51_Start_horn_v1__1__1.stl" scale="0.001 0.001 0.001"/>
    </geometry>
  </collision>
</link>

<link name="DS51_Start_horn_v1__3__1">
  <inertial>
    <origin xyz="2.018447964324821e-07 -3.39837318412764e-07 0.0005609933386140076" rpy="0 0 0"/>
    <mass value="0.027770568475082406"/>
    <inertia ixx="3e-06" iyy="3e-06" izz="6e-06" ixy="-0.0" iyz="-0.0" ixz="-0.0"/>
  </inertial>
  <visual>
    <origin xyz="-0.354936 0.015216 -0.150035" rpy="0 0 0"/>
    <geometry>
      <mesh filename="file://$(find trialin1_v1_description)/meshes/DS51_Start_horn_v1__3__1.stl" scale="0.001 0.001 0.001"/>
    </geometry>
    <material name="silver"/>
  </visual>
  <collision>
    <origin xyz="-0.354936 0.015216 -0.150035" rpy="0 0 0"/>
    <geometry>
      <mesh filename="file://$(find trialin1_v1_description)/meshes/DS51_Start_horn_v1__3__1.stl" scale="0.001 0.001 0.001"/>
    </geometry>
  </collision>
</link>

<link name="DS51_Start_horn_v1__4__1">
  <inertial>
    <origin xyz="2.018447997353956e-07 -3.3983732459531846e-07 0.0005609933386017674" rpy="0 0 0"/>
    <mass value="0.027770568475082406"/>
    <inertia ixx="3e-06" iyy="3e-06" izz="6e-06" ixy="-0.0" iyz="-0.0" ixz="-0.0"/>
  </inertial>
  <visual>
    <origin xyz="-0.054436 0.015216 -0.150035" rpy="0 0 0"/>
    <geometry>
      <mesh filename="file://$(find trialin1_v1_description)/meshes/DS51_Start_horn_v1__4__1.stl" scale="0.001 0.001 0.001"/>
    </geometry>
    <material name="silver"/>
  </visual>
  <collision>
    <origin xyz="-0.054436 0.015216 -0.150035" rpy="0 0 0"/>
    <geometry>
      <mesh filename="file://$(find trialin1_v1_description)/meshes/DS51_Start_horn_v1__4__1.stl" scale="0.001 0.001 0.001"/>
    </geometry>
  </collision>
</link>

<link name="DUDUKAN_PG_36_3MM_v1__1__1">
  <inertial>
    <origin xyz="2.018446058835166e-07 -0.006228931593289688 -0.007756529283786506" rpy="0 0 0"/>
    <mass value="0.061802777435238064"/>
    <inertia ixx="1.1e-05" iyy="2.3e-05" izz="2.1e-05" ixy="-0.0" iyz="-3e-06" ixz="-0.0"/>
  </inertial>
  <visual>
    <origin xyz="-0.054436 0.265216 -0.077035" rpy="0 0 0"/>
    <geometry>
      <mesh filename="file://$(find trialin1_v1_description)/meshes/DUDUKAN_PG_36_3MM_v1__1__1.stl" scale="0.001 0.001 0.001"/>
    </geometry>
    <material name="silver"/>
  </visual>
  <collision>
    <origin xyz="-0.054436 0.265216 -0.077035" rpy="0 0 0"/>
    <geometry>
      <mesh filename="file://$(find trialin1_v1_description)/meshes/DUDUKAN_PG_36_3MM_v1__1__1.stl" scale="0.001 0.001 0.001"/>
    </geometry>
  </collision>
</link>

<link name="DUDUKAN_PG_36_3MM_v1_1">
  <inertial>
    <origin xyz="-0.0001130008522886583 -0.006227988258446726 -0.007756529283785743" rpy="0 0 0"/>
    <mass value="0.061802777435238064"/>
    <inertia ixx="1.1e-05" iyy="2.3e-05" izz="2.1e-05" ixy="0.0" iyz="-3e-06" ixz="-0.0"/>
  </inertial>
  <visual>
    <origin xyz="-0.354393 0.265211 -0.077035" rpy="0 0 0"/>
    <geometry>
      <mesh filename="file://$(find trialin1_v1_description)/meshes/DUDUKAN_PG_36_3MM_v1_1.stl" scale="0.001 0.001 0.001"/>
    </geometry>
    <material name="silver"/>
  </visual>
  <collision>
    <origin xyz="-0.354393 0.265211 -0.077035" rpy="0 0 0"/>
    <geometry>
      <mesh filename="file://$(find trialin1_v1_description)/meshes/DUDUKAN_PG_36_3MM_v1_1.stl" scale="0.001 0.001 0.001"/>
    </geometry>
  </collision>
</link>

<link name="DUDUKAN_PG_36_3MM_v1__3__1">
  <inertial>
    <origin xyz="2.0184498455977362e-07 0.0062282519188664506 -0.007756529283782676" rpy="0 0 0"/>
    <mass value="0.061802777435238064"/>
    <inertia ixx="1.1e-05" iyy="2.3e-05" izz="2.1e-05" ixy="-0.0" iyz="3e-06" ixz="0.0"/>
  </inertial>
  <visual>
    <origin xyz="-0.354936 -0.014784 -0.077035" rpy="0 0 0"/>
    <geometry>
      <mesh filename="file://$(find trialin1_v1_description)/meshes/DUDUKAN_PG_36_3MM_v1__3__1.stl" scale="0.001 0.001 0.001"/>
    </geometry>
    <material name="silver"/>
  </visual>
  <collision>
    <origin xyz="-0.354936 -0.014784 -0.077035" rpy="0 0 0"/>
    <geometry>
      <mesh filename="file://$(find trialin1_v1_description)/meshes/DUDUKAN_PG_36_3MM_v1__3__1.stl" scale="0.001 0.001 0.001"/>
    </geometry>
  </collision>
</link>

<link name="DUDUKAN_PG_36_3MM_v1__2__1">
  <inertial>
    <origin xyz="2.0184498907699355e-07 0.0062282519188602645 -0.007756529283795027" rpy="0 0 0"/>
    <mass value="0.061802777435238064"/>
    <inertia ixx="1.1e-05" iyy="2.3e-05" izz="2.1e-05" ixy="-0.0" iyz="3e-06" ixz="0.0"/>
  </inertial>
  <visual>
    <origin xyz="-0.054436 -0.014784 -0.077035" rpy="0 0 0"/>
    <geometry>
      <mesh filename="file://$(find trialin1_v1_description)/meshes/DUDUKAN_PG_36_3MM_v1__2__1.stl" scale="0.001 0.001 0.001"/>
    </geometry>
    <material name="silver"/>
  </visual>
  <collision>
    <origin xyz="-0.054436 -0.014784 -0.077035" rpy="0 0 0"/>
    <geometry>
      <mesh filename="file://$(find trialin1_v1_description)/meshes/DUDUKAN_PG_36_3MM_v1__2__1.stl" scale="0.001 0.001 0.001"/>
    </geometry>
  </collision>
</link>

<link name="PG36_v1__1__1">
  <inertial>
    <origin xyz="-0.32370248444740624 0.016201880937948387 -0.29970975041019654" rpy="0 0 0"/>
    <mass value="0.10249318991736163"/>
    <inertia ixx="0.000109" iyy="1.8e-05" izz="0.000109" ixy="-3e-06" iyz="0.0" ixz="-0.0"/>
  </inertial>
  <visual>
    <origin xyz="-0.67924 0.231555 -0.353745" rpy="0 0 0"/>
    <geometry>
      <mesh filename="file://$(find trialin1_v1_description)/meshes/PG36_v1__1__1.stl" scale="0.001 0.001 0.001"/>
    </geometry>
    <material name="silver"/>
  </visual>
  <collision>
    <origin xyz="-0.67924 0.231555 -0.353745" rpy="0 0 0"/>
    <geometry>
      <mesh filename="file://$(find trialin1_v1_description)/meshes/PG36_v1__1__1.stl" scale="0.001 0.001 0.001"/>
    </geometry>
  </collision>
</link>

<link name="PG36_v1_1">
  <inertial>
    <origin xyz="-0.024194362439301523 0.00933551385689893 -0.3027167504101972" rpy="0 0 0"/>
    <mass value="0.10249318991736163"/>
    <inertia ixx="0.000109" iyy="1.8e-05" izz="0.000109" ixy="-1e-06" iyz="0.0" ixz="-0.0"/>
  </inertial>
  <visual>
    <origin xyz="-0.078872 0.225681 -0.356752" rpy="0 0 0"/>
    <geometry>
      <mesh filename="file://$(find trialin1_v1_description)/meshes/PG36_v1_1.stl" scale="0.001 0.001 0.001"/>
    </geometry>
    <material name="silver"/>
  </visual>
  <collision>
    <origin xyz="-0.078872 0.225681 -0.356752" rpy="0 0 0"/>
    <geometry>
      <mesh filename="file://$(find trialin1_v1_description)/meshes/PG36_v1_1.stl" scale="0.001 0.001 0.001"/>
    </geometry>
  </collision>
</link>

<link name="PG36_v1__3__1">
  <inertial>
    <origin xyz="0.32469476612888726 -0.010335193531322697 0.0032832495898067263" rpy="0 0 0"/>
    <mass value="0.10249318991736163"/>
    <inertia ixx="0.000109" iyy="1.8e-05" izz="0.000109" ixy="-1e-06" iyz="-0.0" ixz="0.0"/>
  </inertial>
  <visual>
    <origin xyz="-0.03 0.024752 -0.050752" rpy="0 0 0"/>
    <geometry>
      <mesh filename="file://$(find trialin1_v1_description)/meshes/PG36_v1__3__1.stl" scale="0.001 0.001 0.001"/>
    </geometry>
    <material name="silver"/>
  </visual>
  <collision>
    <origin xyz="-0.03 0.024752 -0.050752" rpy="0 0 0"/>
    <geometry>
      <mesh filename="file://$(find trialin1_v1_description)/meshes/PG36_v1__3__1.stl" scale="0.001 0.001 0.001"/>
    </geometry>
  </collision>
</link>

<link name="PG36_v1__2__1">
  <inertial>
    <origin xyz="0.02419476612888973 -0.010335193531328734 0.003283249589794403" rpy="0 0 0"/>
    <mass value="0.10249318991736163"/>
    <inertia ixx="0.000109" iyy="1.8e-05" izz="0.000109" ixy="-1e-06" iyz="-0.0" ixz="0.0"/>
  </inertial>
  <visual>
    <origin xyz="-0.03 0.024752 -0.050752" rpy="0 0 0"/>
    <geometry>
      <mesh filename="file://$(find trialin1_v1_description)/meshes/PG36_v1__2__1.stl" scale="0.001 0.001 0.001"/>
    </geometry>
    <material name="silver"/>
  </visual>
  <collision>
    <origin xyz="-0.03 0.024752 -0.050752" rpy="0 0 0"/>
    <geometry>
      <mesh filename="file://$(find trialin1_v1_description)/meshes/PG36_v1__2__1.stl" scale="0.001 0.001 0.001"/>
    </geometry>
  </collision>
</link>

<link name="Steering_Depan_Kanan_1">
  <inertial>
    <origin xyz="-0.00020879246639582405 -0.011536908480113378 -0.023461288871738054" rpy="0 0 0"/>
    <mass value="1.2246"/>
    <inertia ixx="0.001157" iyy="0.000846" izz="0.001046" ixy="-6e-06" iyz="-0.000304" ixz="-6e-06"/>
  </inertial>
  <visual>
    <origin xyz="-0.354936 0.235216 -0.147035" rpy="0 0 0"/>
    <geometry>
      <mesh filename="file://$(find trialin1_v1_description)/meshes/Steering_Depan_Kanan_1.stl" scale="0.001 0.001 0.001"/>
    </geometry>
    <material name="silver"/>
  </visual>
  <collision>
    <origin xyz="-0.354936 0.235216 -0.147035" rpy="0 0 0"/>
    <geometry>
      <mesh filename="file://$(find trialin1_v1_description)/meshes/Steering_Depan_Kanan_1.stl" scale="0.001 0.001 0.001"/>
    </geometry>
  </collision>
</link>

<link name="Steering_Belakang_Kanan_1">
  <inertial>
    <origin xyz="2.0184479576634828e-07 -0.011538801375676172 -0.023461288871738845" rpy="0 0 0"/>
    <mass value="1.2246"/>
    <inertia ixx="0.001157" iyy="0.000846" izz="0.001046" ixy="0.0" iyz="-0.000304" ixz="0.0"/>
  </inertial>
  <visual>
    <origin xyz="-0.054436 0.235216 -0.147035" rpy="0 0 0"/>
    <geometry>
      <mesh filename="file://$(find trialin1_v1_description)/meshes/Steering_Belakang_Kanan_1.stl" scale="0.001 0.001 0.001"/>
    </geometry>
    <material name="silver"/>
  </visual>
  <collision>
    <origin xyz="-0.054436 0.235216 -0.147035" rpy="0 0 0"/>
    <geometry>
      <mesh filename="file://$(find trialin1_v1_description)/meshes/Steering_Belakang_Kanan_1.stl" scale="0.001 0.001 0.001"/>
    </geometry>
  </collision>
</link>

<link name="Steering_Depan_Kiri_1">
  <inertial>
    <origin xyz="2.0184479604390404e-07 0.01153812170125266 -0.023461288871735084" rpy="0 0 0"/>
    <mass value="1.2246"/>
    <inertia ixx="0.001157" iyy="0.000846" izz="0.001046" ixy="0.0" iyz="0.000304" ixz="-0.0"/>
  </inertial>
  <visual>
    <origin xyz="-0.354936 0.015216 -0.147035" rpy="0 0 0"/>
    <geometry>
      <mesh filename="file://$(find trialin1_v1_description)/meshes/Steering_Depan_Kiri_1.stl" scale="0.001 0.001 0.001"/>
    </geometry>
    <material name="silver"/>
  </visual>
  <collision>
    <origin xyz="-0.354936 0.015216 -0.147035" rpy="0 0 0"/>
    <geometry>
      <mesh filename="file://$(find trialin1_v1_description)/meshes/Steering_Depan_Kiri_1.stl" scale="0.001 0.001 0.001"/>
    </geometry>
  </collision>
</link>

<link name="Steering_Belakang_Kiri_1">
  <inertial>
    <origin xyz="2.018447993884509e-07 0.011538121701246582 -0.023461288871747338" rpy="0 0 0"/>
    <mass value="1.2246"/>
    <inertia ixx="0.001157" iyy="0.000846" izz="0.001046" ixy="0.0" iyz="0.000304" ixz="-0.0"/>
  </inertial>
  <visual>
    <origin xyz="-0.054436 0.015216 -0.147035" rpy="0 0 0"/>
    <geometry>
      <mesh filename="file://$(find trialin1_v1_description)/meshes/Steering_Belakang_Kiri_1.stl" scale="0.001 0.001 0.001"/>
    </geometry>
    <material name="silver"/>
  </visual>
  <collision>
    <origin xyz="-0.054436 0.015216 -0.147035" rpy="0 0 0"/>
    <geometry>
      <mesh filename="file://$(find trialin1_v1_description)/meshes/Steering_Belakang_Kiri_1.stl" scale="0.001 0.001 0.001"/>
    </geometry>
  </collision>
</link>

<link name="Rubber_v1_1">
  <inertial>
    <origin xyz="-0.05443579815520295 0.042035660162784816 0.3027162495897994" rpy="0 0 0"/>
    <mass value="0.5258145099128054"/>
    <inertia ixx="0.000629" iyy="0.001211" izz="0.000629" ixy="-0.0" iyz="-0.0" ixz="-0.0"/>
  </inertial>
  <visual>
    <origin xyz="-0.108872 0.334752 0.248681" rpy="0 0 0"/>
    <geometry>
      <mesh filename="file://$(find trialin1_v1_description)/meshes/Rubber_v1_1.stl" scale="0.001 0.001 0.001"/>
    </geometry>
    <material name="silver"/>
  </visual>
  <collision>
    <origin xyz="-0.108872 0.334752 0.248681" rpy="0 0 0"/>
    <geometry>
      <mesh filename="file://$(find trialin1_v1_description)/meshes/Rubber_v1_1.stl" scale="0.001 0.001 0.001"/>
    </geometry>
  </collision>
</link>

<link name="Rubber_v1__1__1">
  <inertial>
    <origin xyz="-0.3549357981552056 0.04203566016279123 -0.05428375041019677" rpy="0 0 0"/>
    <mass value="0.5258145099128054"/>
    <inertia ixx="0.000629" iyy="0.001211" izz="0.000629" ixy="-0.0" iyz="0.0" ixz="-0.0"/>
  </inertial>
  <visual>
    <origin xyz="-0.709872 -0.002248 -0.108319" rpy="0 0 0"/>
    <geometry>
      <mesh filename="file://$(find trialin1_v1_description)/meshes/Rubber_v1__1__1.stl" scale="0.001 0.001 0.001"/>
    </geometry>
    <material name="silver"/>
  </visual>
  <collision>
    <origin xyz="-0.709872 -0.002248 -0.108319" rpy="0 0 0"/>
    <geometry>
      <mesh filename="file://$(find trialin1_v1_description)/meshes/Rubber_v1__1__1.stl" scale="0.001 0.001 0.001"/>
    </geometry>
  </collision>
</link>

<link name="Rubber_v1__2__1">
  <inertial>
    <origin xyz="-0.353274173632344 0.0484419290413704 0.28170824958980023" rpy="0 0 0"/>
    <mass value="0.5258145099128054"/>
    <inertia ixx="0.000629" iyy="0.001211" izz="0.000629" ixy="1.1e-05" iyz="0.0" ixz="-0.0"/>
  </inertial>
  <visual>
    <origin xyz="-0.707187 0.340149 0.227673" rpy="0 0 0"/>
    <geometry>
      <mesh filename="file://$(find trialin1_v1_description)/meshes/Rubber_v1__2__1.stl" scale="0.001 0.001 0.001"/>
    </geometry>
    <material name="silver"/>
  </visual>
  <collision>
    <origin xyz="-0.707187 0.340149 0.227673" rpy="0 0 0"/>
    <geometry>
      <mesh filename="file://$(find trialin1_v1_description)/meshes/Rubber_v1__2__1.stl" scale="0.001 0.001 0.001"/>
    </geometry>
  </collision>
</link>

<link name="Rubber_v1__3__1">
  <inertial>
    <origin xyz="-0.054435798155200554 0.04203566016278469 -0.05428375041020907" rpy="0 0 0"/>
    <mass value="0.5258145099128054"/>
    <inertia ixx="0.000629" iyy="0.001211" izz="0.000629" ixy="-0.0" iyz="0.0" ixz="-0.0"/>
  </inertial>
  <visual>
    <origin xyz="-0.108872 -0.002248 -0.108319" rpy="0 0 0"/>
    <geometry>
      <mesh filename="file://$(find trialin1_v1_description)/meshes/Rubber_v1__3__1.stl" scale="0.001 0.001 0.001"/>
    </geometry>
    <material name="silver"/>
  </visual>
  <collision>
    <origin xyz="-0.108872 -0.002248 -0.108319" rpy="0 0 0"/>
    <geometry>
      <mesh filename="file://$(find trialin1_v1_description)/meshes/Rubber_v1__3__1.stl" scale="0.001 0.001 0.001"/>
    </geometry>
  </collision>
</link>

<link name="Kiri_Belakang_1">
  <inertial>
    <origin xyz="0.054436201844803044 -0.03573533983721568 -0.03728375041020913" rpy="0 0 0"/>
    <mass value="1.1039968133352154"/>
    <inertia ixx="0.000584" iyy="0.001056" izz="0.000584" ixy="-0.0" iyz="0.0" ixz="-0.0"/>
  </inertial>
  <visual>
    <origin xyz="-0.0 -0.080019 -0.091319" rpy="0 0 0"/>
    <geometry>
      <mesh filename="file://$(find trialin1_v1_description)/meshes/Kiri_Belakang_1.stl" scale="0.001 0.001 0.001"/>
    </geometry>
    <material name="silver"/>
  </visual>
  <collision>
    <origin xyz="-0.0 -0.080019 -0.091319" rpy="0 0 0"/>
    <geometry>
      <mesh filename="file://$(find trialin1_v1_description)/meshes/Kiri_Belakang_1.stl" scale="0.001 0.001 0.001"/>
    </geometry>
  </collision>
</link>

<link name="Kiri_Depan_1">
  <inertial>
    <origin xyz="0.3549362018447977 -0.03573533983720928 -0.03728375041019676" rpy="0 0 0"/>
    <mass value="1.1039968133352154"/>
    <inertia ixx="0.000584" iyy="0.001056" izz="0.000584" ixy="-0.0" iyz="-0.0" ixz="0.0"/>
  </inertial>
  <visual>
    <origin xyz="-0.0 -0.080019 -0.091319" rpy="0 0 0"/>
    <geometry>
      <mesh filename="file://$(find trialin1_v1_description)/meshes/Kiri_Depan_1.stl" scale="0.001 0.001 0.001"/>
    </geometry>
    <material name="silver"/>
  </visual>
  <collision>
    <origin xyz="-0.0 -0.080019 -0.091319" rpy="0 0 0"/>
    <geometry>
      <mesh filename="file://$(find trialin1_v1_description)/meshes/Kiri_Depan_1.stl" scale="0.001 0.001 0.001"/>
    </geometry>
  </collision>
</link>

<link name="Kanan_Depan_1">
  <inertial>
    <origin xyz="-0.35322517363234035 0.04514092904136974 0.2877072495898001" rpy="0 0 0"/>
    <mass value="1.1039968133352154"/>
    <inertia ixx="0.000584" iyy="0.001055" izz="0.000584" ixy="9e-06" iyz="-0.0" ixz="0.0"/>
  </inertial>
  <visual>
    <origin xyz="-0.707138 0.336848 0.233672" rpy="0 0 0"/>
    <geometry>
      <mesh filename="file://$(find trialin1_v1_description)/meshes/Kanan_Depan_1.stl" scale="0.001 0.001 0.001"/>
    </geometry>
    <material name="silver"/>
  </visual>
  <collision>
    <origin xyz="-0.707138 0.336848 0.233672" rpy="0 0 0"/>
    <geometry>
      <mesh filename="file://$(find trialin1_v1_description)/meshes/Kanan_Depan_1.stl" scale="0.001 0.001 0.001"/>
    </geometry>
  </collision>
</link>

<link name="Kanan_Belakang_1">
  <inertial>
    <origin xyz="-0.05443579815519938 0.0387356601627854 0.28871624958979947" rpy="0 0 0"/>
    <mass value="1.1039968133352154"/>
    <inertia ixx="0.000584" iyy="0.001056" izz="0.000584" ixy="-0.0" iyz="0.0" ixz="-0.0"/>
  </inertial>
  <visual>
    <origin xyz="-0.108872 0.331452 0.234681" rpy="0 0 0"/>
    <geometry>
      <mesh filename="file://$(find trialin1_v1_description)/meshes/Kanan_Belakang_1.stl" scale="0.001 0.001 0.001"/>
    </geometry>
    <material name="silver"/>
  </visual>
  <collision>
    <origin xyz="-0.108872 0.331452 0.234681" rpy="0 0 0"/>
    <geometry>
      <mesh filename="file://$(find trialin1_v1_description)/meshes/Kanan_Belakang_1.stl" scale="0.001 0.001 0.001"/>
    </geometry>
  </collision>
</link>

<link name="ArahKinect_1">
  <inertial>
    <origin xyz="2.0184479500306995e-07 -3.398372145912987e-07 0.002499711046427211" rpy="0 0 0"/>
    <mass value="0.471"/>
    <inertia ixx="0.000566" iyy="0.000393" izz="0.000958" ixy="0.0" iyz="-0.0" ixz="0.0"/>
  </inertial>
  <visual>
    <origin xyz="-0.068936 0.125216 -0.610305" rpy="0 0 0"/>
    <geometry>
      <mesh filename="file://$(find trialin1_v1_description)/meshes/ArahKinect_1.stl" scale="0.001 0.001 0.001"/>
    </geometry>
    <material name="silver"/>
  </visual>
  <collision>
    <origin xyz="-0.068936 0.125216 -0.610305" rpy="0 0 0"/>
    <geometry>
      <mesh filename="file://$(find trialin1_v1_description)/meshes/ArahKinect_1.stl" scale="0.001 0.001 0.001"/>
    </geometry>
  </collision>
</link>

<link name="Servo_v1__4__1">
  <inertial>
    <origin xyz="-0.00022606555569416875 -3.352873680917412e-07 0.01995287724501449" rpy="0 0 0"/>
    <mass value="0.25233806594972435"/>
    <inertia ixx="4.1e-05" iyy="6.8e-05" izz="4.3e-05" ixy="0.0" iyz="-0.0" ixz="1e-06"/>
  </inertial>
  <visual>
    <origin xyz="-0.079686 0.125216 -0.561885" rpy="0 0 0"/>
    <geometry>
      <mesh filename="file://$(find trialin1_v1_description)/meshes/Servo_v1__4__1.stl" scale="0.001 0.001 0.001"/>
    </geometry>
    <material name="silver"/>
  </visual>
  <collision>
    <origin xyz="-0.079686 0.125216 -0.561885" rpy="0 0 0"/>
    <geometry>
      <mesh filename="file://$(find trialin1_v1_description)/meshes/Servo_v1__4__1.stl" scale="0.001 0.001 0.001"/>
    </geometry>
  </collision>
</link>

<link name="Sense_Kinect_v1_1">
  <inertial>
    <origin xyz="-0.002250191411903399 4.488209067438076e-05 0.04507379301705006" rpy="0 0 0"/>
    <mass value="5.170546565587239"/>
    <inertia ixx="0.024597" iyy="0.003275" izz="0.024429" ixy="-7e-06" iyz="-3e-06" ixz="2.8e-05"/>
  </inertial>
  <visual>
    <origin xyz="-0.068936 0.125216 -0.615305" rpy="0 0 0"/>
    <geometry>
      <mesh filename="file://$(find trialin1_v1_description)/meshes/Sense_Kinect_v1_1.stl" scale="0.001 0.001 0.001"/>
    </geometry>
    <material name="silver"/>
  </visual>
  <collision>
    <origin xyz="-0.068936 0.125216 -0.615305" rpy="0 0 0"/>
    <geometry>
      <mesh filename="file://$(find trialin1_v1_description)/meshes/Sense_Kinect_v1_1.stl" scale="0.001 0.001 0.001"/>
    </geometry>
  </collision>
</link>

<link name="Servo_v1__1__1">
  <inertial>
    <origin xyz="-0.20491206555569624 0.11521665561293878 -0.16668737806541642" rpy="0 0 0"/>
    <mass value="0.25233806594972435"/>
    <inertia ixx="4.1e-05" iyy="6.8e-05" izz="4.3e-05" ixy="-0.0" iyz="-0.0" ixz="-1e-06"/>
  </inertial>
  <visual>
    <origin xyz="-0.269872 0.130433 -0.34297" rpy="0 0 0"/>
    <geometry>
      <mesh filename="file://$(find trialin1_v1_description)/meshes/Servo_v1__1__1.stl" scale="0.001 0.001 0.001"/>
    </geometry>
    <material name="silver"/>
  </visual>
  <collision>
    <origin xyz="-0.269872 0.130433 -0.34297" rpy="0 0 0"/>
    <geometry>
      <mesh filename="file://$(find trialin1_v1_description)/meshes/Servo_v1__1__1.stl" scale="0.001 0.001 0.001"/>
    </geometry>
  </collision>
</link>

<link name="Servo_v1__2__1">
  <inertial>
    <origin xyz="-0.20445953075471823 0.1152166647126365 -0.16668737806541659" rpy="0 0 0"/>
    <mass value="0.25233806594972435"/>
    <inertia ixx="4.1e-05" iyy="6.8e-05" izz="4.3e-05" ixy="-0.0" iyz="0.0" ixz="1e-06"/>
  </inertial>
  <visual>
    <origin xyz="-0.548872 0.130433 -0.34297" rpy="0 0 0"/>
    <geometry>
      <mesh filename="file://$(find trialin1_v1_description)/meshes/Servo_v1__2__1.stl" scale="0.001 0.001 0.001"/>
    </geometry>
    <material name="silver"/>
  </visual>
  <collision>
    <origin xyz="-0.548872 0.130433 -0.34297" rpy="0 0 0"/>
    <geometry>
      <mesh filename="file://$(find trialin1_v1_description)/meshes/Servo_v1__2__1.stl" scale="0.001 0.001 0.001"/>
    </geometry>
  </collision>
</link>

<link name="Servo_v1__3__1">
  <inertial>
    <origin xyz="-0.20445953075471468 0.1352166647126372 -0.1666873780654162" rpy="0 0 0"/>
    <mass value="0.25233806594972435"/>
    <inertia ixx="4.1e-05" iyy="6.8e-05" izz="4.3e-05" ixy="-0.0" iyz="0.0" ixz="1e-06"/>
  </inertial>
  <visual>
    <origin xyz="-0.548872 0.370433 -0.34297" rpy="0 0 0"/>
    <geometry>
      <mesh filename="file://$(find trialin1_v1_description)/meshes/Servo_v1__3__1.stl" scale="0.001 0.001 0.001"/>
    </geometry>
    <material name="silver"/>
  </visual>
  <collision>
    <origin xyz="-0.548872 0.370433 -0.34297" rpy="0 0 0"/>
    <geometry>
      <mesh filename="file://$(find trialin1_v1_description)/meshes/Servo_v1__3__1.stl" scale="0.001 0.001 0.001"/>
    </geometry>
  </collision>
</link>

<link name="Servo_v1_1">
  <inertial>
    <origin xyz="-0.20491206555569225 0.13521665561293963 -0.16668737806541628" rpy="0 0 0"/>
    <mass value="0.25233806594972435"/>
    <inertia ixx="4.1e-05" iyy="6.8e-05" izz="4.3e-05" ixy="-0.0" iyz="-0.0" ixz="-1e-06"/>
  </inertial>
  <visual>
    <origin xyz="-0.269872 0.370433 -0.34297" rpy="0 0 0"/>
    <geometry>
      <mesh filename="file://$(find trialin1_v1_description)/meshes/Servo_v1_1.stl" scale="0.001 0.001 0.001"/>
    </geometry>
    <material name="silver"/>
  </visual>
  <collision>
    <origin xyz="-0.269872 0.370433 -0.34297" rpy="0 0 0"/>
    <geometry>
      <mesh filename="file://$(find trialin1_v1_description)/meshes/Servo_v1_1.stl" scale="0.001 0.001 0.001"/>
    </geometry>
  </collision>
</link>

<joint name="Rigid 6" type="fixed">
  <origin xyz="-0.01075 0.0 0.04542" rpy="0 0 0"/>
  <parent link="Servo_v1__4__1"/>
  <child link="DS51_Start_horn_v1_1"/>
</joint>

<joint name="Rigid 7" type="fixed">
  <origin xyz="-0.215436 0.135217 -0.192935" rpy="0 0 0"/>
  <parent link="Servo_v1_1"/>
  <child link="DS51_Start_horn_v1__2__1"/>
</joint>

<joint name="Rigid 8" type="fixed">
  <origin xyz="-0.193936 0.135217 -0.192935" rpy="0 0 0"/>
  <parent link="Servo_v1__3__1"/>
  <child link="DS51_Start_horn_v1__1__1"/>
</joint>

<joint name="Rigid 9" type="fixed">
  <origin xyz="-0.193936 0.115217 -0.192935" rpy="0 0 0"/>
  <parent link="Servo_v1__2__1"/>
  <child link="DS51_Start_horn_v1__3__1"/>
</joint>

<joint name="Rigid 10" type="fixed">
  <origin xyz="-0.215436 0.115217 -0.192935" rpy="0 0 0"/>
  <parent link="Servo_v1__1__1"/>
  <child link="DS51_Start_horn_v1__4__1"/>
</joint>

<joint name="Rigid 26" type="fixed">
  <origin xyz="0.0 -0.03 -0.07" rpy="0 0 0"/>
  <parent link="Steering_Belakang_Kanan_1"/>
  <child link="DUDUKAN_PG_36_3MM_v1__1__1"/>
</joint>

<joint name="Rigid 27" type="fixed">
  <origin xyz="-0.000543 -0.029995 -0.07" rpy="0 0 0"/>
  <parent link="Steering_Depan_Kanan_1"/>
  <child link="DUDUKAN_PG_36_3MM_v1_1"/>
</joint>

<joint name="Rigid 28" type="fixed">
  <origin xyz="0.0 0.03 -0.07" rpy="0 0 0"/>
  <parent link="Steering_Depan_Kiri_1"/>
  <child link="DUDUKAN_PG_36_3MM_v1__3__1"/>
</joint>

<joint name="Rigid 29" type="fixed">
  <origin xyz="0.0 0.03 -0.07" rpy="0 0 0"/>
  <parent link="Steering_Belakang_Kiri_1"/>
  <child link="DUDUKAN_PG_36_3MM_v1__2__1"/>
</joint>

<joint name="Rigid 30" type="fixed">
  <origin xyz="0.324847 0.033656 0.27671" rpy="0 0 0"/>
  <parent link="DUDUKAN_PG_36_3MM_v1_1"/>
  <child link="PG36_v1__1__1"/>
</joint>

<joint name="Rigid 31" type="fixed">
  <origin xyz="0.024436 0.039535 0.279717" rpy="0 0 0"/>
  <parent link="DUDUKAN_PG_36_3MM_v1__1__1"/>
  <child link="PG36_v1_1"/>
</joint>

<joint name="Rigid 32" type="fixed">
  <origin xyz="-0.324936 -0.039536 -0.026283" rpy="0 0 0"/>
  <parent link="DUDUKAN_PG_36_3MM_v1__3__1"/>
  <child link="PG36_v1__3__1"/>
</joint>

<joint name="Rigid 33" type="fixed">
  <origin xyz="-0.024436 -0.039536 -0.026283" rpy="0 0 0"/>
  <parent link="DUDUKAN_PG_36_3MM_v1__2__1"/>
  <child link="PG36_v1__2__1"/>
</joint>

<joint name="Revolute 34" type="revolute">
  <origin xyz="0.0 0.0 -0.003" rpy="0 0 0"/>
  <parent link="DS51_Start_horn_v1__1__1"/>
  <child link="Steering_Depan_Kanan_1"/>
  <axis xyz="0.0 -0.0 -1.0"/>
  <limit upper="1.570796" lower="-1.570796" effort="100" velocity="100"/>
</joint>

<joint name="Revolute 35" type="revolute">
  <origin xyz="0.0 0.0 -0.003" rpy="0 0 0"/>
  <parent link="DS51_Start_horn_v1__2__1"/>
  <child link="Steering_Belakang_Kanan_1"/>
  <axis xyz="-0.0 -0.0 -1.0"/>
  <limit upper="1.570796" lower="-1.570796" effort="100" velocity="100"/>
</joint>

<joint name="Revolute 36" type="revolute">
  <origin xyz="0.0 0.0 -0.003" rpy="0 0 0"/>
  <parent link="DS51_Start_horn_v1__3__1"/>
  <child link="Steering_Depan_Kiri_1"/>
  <axis xyz="-0.0 -0.0 -1.0"/>
  <limit upper="1.570796" lower="-1.570796" effort="100" velocity="100"/>
</joint>

<joint name="Revolute 37" type="revolute">
  <origin xyz="0.0 0.0 -0.003" rpy="0 0 0"/>
  <parent link="DS51_Start_horn_v1__4__1"/>
  <child link="Steering_Belakang_Kiri_1"/>
  <axis xyz="-0.0 -0.0 -1.0"/>
  <limit upper="1.570796" lower="-1.570796" effort="100" velocity="100"/>
</joint>

<joint name="Rigid 38" type="fixed">
  <origin xyz="0.0 -0.0033 -0.014" rpy="0 0 0"/>
  <parent link="Kanan_Belakang_1"/>
  <child link="Rubber_v1_1"/>
</joint>

<joint name="Rigid 39" type="fixed">
  <origin xyz="0.709872 -0.077771 0.017" rpy="0 0 0"/>
  <parent link="Kiri_Depan_1"/>
  <child link="Rubber_v1__1__1"/>
</joint>

<joint name="Rigid 40" type="fixed">
  <origin xyz="4.9e-05 -0.003301 0.005999" rpy="0 0 0"/>
  <parent link="Kanan_Depan_1"/>
  <child link="Rubber_v1__2__1"/>
</joint>

<joint name="Rigid 41" type="fixed">
  <origin xyz="0.108872 -0.077771 0.017" rpy="0 0 0"/>
  <parent link="Kiri_Belakang_1"/>
  <child link="Rubber_v1__3__1"/>
</joint>

<joint name="Revolute 42" type="continuous">
  <origin xyz="-0.03 0.104771 0.040567" rpy="0 0 0"/>
  <parent link="PG36_v1__2__1"/>
  <child link="Kiri_Belakang_1"/>
  <axis xyz="0.0 1.0 -0.0"/>
</joint>

<joint name="Revolute 43" type="continuous">
  <origin xyz="-0.03 0.104771 0.040567" rpy="0 0 0"/>
  <parent link="PG36_v1__3__1"/>
  <child link="Kiri_Depan_1"/>
  <axis xyz="0.0 1.0 -0.0"/>
</joint>

<joint name="Revolute 44" type="continuous">
  <origin xyz="0.027898 -0.105293 -0.587417" rpy="0 0 0"/>
  <parent link="PG36_v1__1__1"/>
  <child link="Kanan_Depan_1"/>
  <axis xyz="-0.018113 -0.999836 0.0"/>
</joint>

<joint name="Revolute 45" type="continuous">
  <origin xyz="0.03 -0.105771 -0.591433" rpy="0 0 0"/>
  <parent link="PG36_v1_1"/>
  <child link="Kanan_Belakang_1"/>
  <axis xyz="0.0 -1.0 0.0"/>
</joint>

<joint name="Revolute 46" type="revolute">
  <origin xyz="0.0 0.0 0.003" rpy="0 0 0"/>
  <parent link="DS51_Start_horn_v1_1"/>
  <child link="ArahKinect_1"/>
  <axis xyz="0.0 0.0 1.0"/>
  <limit upper="1.570796" lower="-1.570796" effort="100" velocity="100"/>
</joint>

<joint name="Rigid 52" type="fixed">
  <origin xyz="0.079686 -0.125216 0.561885" rpy="0 0 0"/>
  <parent link="base_link"/>
  <child link="Servo_v1__4__1"/>
</joint>

<joint name="Rigid 53" type="fixed">
  <origin xyz="0.0 0.0 0.005" rpy="0 0 0"/>
  <parent link="ArahKinect_1"/>
  <child link="Sense_Kinect_v1_1"/>
</joint>

<joint name="Rigid 54" type="fixed">
  <origin xyz="0.269872 -0.130433 0.34297" rpy="0 0 0"/>
  <parent link="base_link"/>
  <child link="Servo_v1__1__1"/>
</joint>

<joint name="Rigid 55" type="fixed">
  <origin xyz="0.548872 -0.130433 0.34297" rpy="0 0 0"/>
  <parent link="base_link"/>
  <child link="Servo_v1__2__1"/>
</joint>

<joint name="Rigid 56" type="fixed">
  <origin xyz="0.548872 -0.370433 0.34297" rpy="0 0 0"/>
  <parent link="base_link"/>
  <child link="Servo_v1__3__1"/>
</joint>

<joint name="Rigid 57" type="fixed">
  <origin xyz="0.269872 -0.370433 0.34297" rpy="0 0 0"/>
  <parent link="base_link"/>
  <child link="Servo_v1_1"/>
</joint>

</robot>
